Workbook

Sheet README
B2: Suntransfers — 1-23 August 2026 vs 1-23 August 2025 traffic & conversion
B3: Sessions · Searches · Purchases · Start Search · Visit→Search · Search→Booking · CR — by channel → landing page group → device → market
B5: STATUS
B6: Loaded | C6: Complete on all seven volume inputs: Sessions, Start Search, Searches, Select item, Add to cart, Begin checkout and Purchases, both years. Every YoY and rate cell calculates at scorecard level.
B7: Remaining | C7: Country-level blanks only, where a market sits outside a Looker table's visible rows. All listed on 'Gaps to fill'.
B9: METRIC DEFINITIONS
B10: Sessions | C10: GA4 sessions, as reported by the Looker scorecards.
B11: Searches | C11: The 'Searches' tile — sessions that reached a listing view. The SR / visit-to-search numerator, not start_search.
B12: Purchases | C12: Completed bookings (the 'Purchases' tile).
B13: Start Search | C13: The start_search event — an engagement signal (the search form was actually used), tracked separately from 'Searches' (which is the view_item_list-based visit-to-search numerator). Shown as its own volume metric on Totals, Countries, L1-L4 and Market Summary so you can read engagement by channel / landing page / device / country; it does not feed Visit→Search, Search→Booking or CR, and is not on the Funnel tab.
B14: Select item | C14: The select_item event — a listing result was opened. First step after the listing view.
B15: Add to cart | C15: The add_to_cart event — a transfer was put in the basket.
B16: Begin checkout | C16: The begin_checkout event — the checkout flow was entered.
B17: Visit→Search | C17: Searches ÷ Sessions. How many arrivals get as far as a listing.
B18: Search→Select | C18: Select item ÷ Searches. How many listing-viewers open a result.
B19: Select→Cart | C19: Add to cart ÷ Select item. How many openers add to the basket.
B20: Cart→Checkout | C20: Begin checkout ÷ Add to cart. How many baskets enter checkout.
B21: Checkout→Purchase | C21: Purchases ÷ Begin checkout. How many checkouts complete. The step where payment friction shows up.
... B23: CR | C23: Purchases ÷ Sessions. The end-to-end conversion rate, and the product of the two rates above.
B25: HOW IT IS BUILT
B26: Inputs | C26: Two tabs hold every number: 'Totals' (scorecard) and 'Countries' (country detail). Nothing else is typed.
B27: Views | C27: L1 → L4 and 'Market Summary' are formulas only. Do not type in them.
B28: Row / column logic | C28: Dimensions go down the rows; metrics go across in blocks. Volumes take four columns (1-23Aug26, 1-23Aug25, Δ, % Δ), rates take three (1-23Aug26, 1-23Aug25, Δ pp). Adding a KPI is one more block, not a new tab.
B29: To refresh a new month | C29: Overwrite the blue numbers on 'Totals' and 'Countries' (or regenerate them from new screenshots), update config.py's period labels, and rebuild.
B31: CELL COLOUR LEGEND
B32: Blue text | C32: Hard-coded input read off the Looker screenshots. The only cells to overwrite when refreshing.
B33: Black text | C33: Formula calculated within the same tab.
B34: Green text | C34: Formula pulling from another tab (Totals or Countries).
B35: Yellow fill | C35: Fill this in. On the input tabs it is a missing number — see 'Gaps to fill'. On 'L4 Market view' it is a dropdown control.
B37: TABS
B38: Funnel | C38: READ THIS FIRST. Sessions → Searches → Bookings and the three rates, for the total, each channel, each landing page group, each device, each market, each market within the Direct channel, and each market within each channel on Desktop only. One row per segment. (Start Search is not on this tab — see Countries, L1-L4 and Market Summary.)
B39: Totals | C39: INPUT. Scorecard: landing page group × channel × device, all four volume metrics (Sessions, Searches, Purchases, Start Search). 'Other pages (derived)' = All − Home − Airport − Route.
B40: Countries | C40: INPUT. Country detail as shown in the Looker tables, including Start Search engagement sessions.
B41: Gaps to fill | C41: Worklist of every yellow cell: which market, which metric, which period, the exact cell to type into, and what it unblocks.
B42: L1 Channel YoY | C42: Level 1 — channel × device, all landing pages, plus channel mix.
B43: L2 Channel x Landing | C43: Level 2 — landing page group × channel, device = Total.
B44: L3 Ch x Landing x Device | C44: Level 3 — landing page group × channel × device.
B45: L4 Market view | C45: Level 4 — country rows, with dropdowns for landing page group, channel and device.
B46: Market Summary | C46: Country × channel across all landing pages: one stacked table per metric/rate (Sessions, Searches, Purchases, Start Search, Visit→Search, Search→Booking, CR).
B48: DATA SOURCE
...

Sheet Funnel
A1: Funnel at a glance — 1-23 August 2026 vs 1-23 August 2025
A2: Sessions → Searches → Bookings, then the three rates. Paid Search + Organic + Direct only. Source: Totals and Countries tabs.
A4: Segment | B4: Split | C4: Sessions | F4: Searches | I4: Bookings | L4: Visit→Search | O4: Search→Booking | R4: CR
C5: 1-23Aug25 | D5: 1-23Aug26 | E5: % Δ | F5: 1-23Aug25 | G5: 1-23Aug26 | H5: % Δ | I5: 1-23Aug25 | J5: 1-23Aug26 | K5: % Δ | L5: 1-23Aug25 | M5: 1-23Aug26 | N5: Δ pp | O5: 1-23Aug25 | P5: 1-23Aug26 | Q5: Δ pp | R5: 1-23Aug25 | S5: 1-23Aug26 | T5: Δ pp
A6: TOTAL — 3 channels | B6: All | C6: =SUMIFS(Totals!$D$5:$D$49,Totals!$A$5:$A$49,"All landing pages",Totals!$B$5:$B$49,"Paid Search",Totals!$C$5:$C$49,"Total")+SUMIFS(Totals!$D$5:$D$49,Totals!$A$5:$A$49,"All landing pages",Totals!$B$5:$B$49,"Organic",Totals!$C$5:$C$49,"Total")+SUMIFS(Totals!$D$5:$D$49,Totals!$A$5:$A$49,"All landing pages",Totals!$B$5:$B$49,"Direct",Totals!$C$5:$C$49,"Total") | D6: =SUMIFS(Totals!$E$5:$E$49,Totals!$A$5:$A$49,"All landing pages",Totals!$B$5:$B$49,"Paid Search",Totals!$C$5:$C$49,"Total")+SUMIFS(Totals!$E$5:$E$49,Totals!$A$5:$A$49,"All landing pages",Totals!$B$5:$B$49,"Organic",Totals!$C$5:$C$49,"Total")+SUMIFS(Totals!$E$5:$E$49,Totals!$A$5:$A$49,"All landing pages",Totals!$B$5:$B$49,"Direct",Totals!$C$5:$C$49,"Total") | E6: =IF(OR(C6="",D6="",D6=0,C6=0),"",D6/C6-1) | F6: =SUMIFS(Totals!$O$5:$O$49,Totals!$A$5:$A$49,"All landing pages",Totals!$B$5:$B$49,"Paid Search",Totals!$C$5:$C$49,"Total")+SUMIFS(Totals!$O$5:$O$49,Totals!$A$5:$A$49,"All landing pages",Totals!$B$5:$B$49,"Organic",Totals!$C$5:$C$49,"Total")+SUMIFS(Totals!$O$5:$O$49,Totals!$A$5:$A$49,"All landing pages",Totals!$B$5:$B$49,"Direct",Totals!$C$5:$C$49,"Total") | G6: =SUMIFS(Totals!$P$5:$P$49,Totals!$A$5:$A$49,"All landing pages",Totals!$B$5:$B$49,"Paid Search",Totals!$C$5:$C$49,"Total")+SUMIFS(Totals!$P$5:$P$49,Totals!$A$5:$A$49,"All landing pages",Totals!$B$5:$B$49,"Organic",Totals!$C$5:$C$49,"Total")+SUMIFS(Totals!$P$5:$P$49,Totals!$A$5:$A$49,"All landing pages",Totals!$B$5:$B$49,"Direct",Totals!$C$5:$C$49,"Total") | H6: =IF(OR(F6="",G6="",G6=0,F6=0),"",G6/F6-1) | I6: =SUMIFS(Totals!$AQ$5:$AQ$49,Totals!$A$5:$A$49,"All landing pages",Totals!$B$5:$B$49,"Paid Search",Totals!$C$5:$C$49,"Total")+SUMIFS(Totals!$AQ$5:$AQ$49,Totals!$A$5:$A$49,"All landing pages",Totals!$B$5:$B$49,"Organic",Totals!$C$5:$C$49,"Total")+SUMIFS(Totals!$AQ$5:$AQ$49,Totals!$A$5:$A$49,"All landing pages",Totals!$B$5:$B$49,"Direct",Totals!$C$5:$C$49,"Total") | J6: =SUMIFS(Totals!$AR$5:$AR$49,Totals!$A$5:$A$49,"All landing pages",Totals!$B$5:$B$49,"Paid Search",Totals!$C$5:$C$49,"Total")+SUMIFS(Totals!$AR$5:$AR$49,Totals!$A$5:$A$49,"All landing pages",Totals!$B$5:$B$49,"Organic",Totals!$C$5:$C$49,"Total")+SUMIFS(Totals!$AR$5:$AR$49,Totals!$A$5:$A$49,"All landing pages",Totals!$B$5:$B$49,"Direct",Totals!$C$5:$C$49,"Total") | K6: =IF(OR(I6="",J6="",J6=0,I6=0),"",J6/I6-1) | L6: =IF(OR(F6="",C6="",C6=0),"",F6/C6) | M6: =IF(OR(G6="",D6="",D6=0),"",G6/D6) | N6: =IF(OR(L6="",M6=""),"",(M6-L6)*100) | O6: =IF(OR(I6="",F6="",F6=0),"",I6/F6) | P6: =IF(OR(J6="",G6="",G6=0),"",J6/G6) | Q6: =IF(OR(O6="",P6=""),"",(P6-O6)*100) | R6: =IF(OR(I6="",C6="",C6=0),"",I6/C6) | S6: =IF(OR(J6="",D6="",D6=0),"",J6/D6) | T6: =IF(OR(R6="",S6=""),"",(S6-R6)*100)
A8: By channel (all landing pages, all devices)
A9: Paid Search | B9: Total | C9: =SUMIFS(Totals!$D$5:$D$49,Totals!$A$5:$A$49,"All landing pages",Totals!$B$5:$B$49,"Paid Search",Totals!$C$5:$C$49,"Total") | D9: =SUMIFS(Totals!$E$5:$E$49,Totals!$A$5:$A$49,"All landing pages",Totals!$B$5:$B$49,"Paid Search",Totals!$C$5:$C$49,"Total") | E9: =IF(OR(C9="",D9="",D9=0,C9=0),"",D9/C9-1) | F9: =SUMIFS(Totals!$O$5:$O$49,Totals!$A$5:$A$49,"All landing pages",Totals!$B$5:$B$49,"Paid Search",Totals!$C$5:$C$49,"Total") | G9: =SUMIFS(Totals!$P$5:$P$49,Totals!$A$5:$A$49,"All landing pages",Totals!$B$5:$B$49,"Paid Search",Totals!$C$5:$C$49,"Total") | H9: =IF(OR(F9="",G9="",G9=0,F9=0),"",G9/F9-1) | I9: =SUMIFS(Totals!$AQ$5:$AQ$49,Totals!$A$5:$A$49,"All landing pages",Totals!$B$5:$B$49,"Paid Search",Totals!$C$5:$C$49,"Total") | J9: =SUMIFS(Totals!$AR$5:$AR$49,Totals!$A$5:$A$49,"All landing pages",Totals!$B$5:$B$49,"Paid Search",Totals!$C$5:$C$49,"Total") | K9: =IF(OR(I9="",J9="",J9=0,I9=0),"",J9/I9-1) | L9: =IF(OR(F9="",C9="",C9=0),"",F9/C9) | M9: =IF(OR(G9="",D9="",D9=0),"",G9/D9) | N9: =IF(OR(L9="",M9=""),"",(M9-L9)*100) | O9: =IF(OR(I9="",F9="",F9=0),"",I9/F9) | P9: =IF(OR(J9="",G9="",G9=0),"",J9/G9) | Q9: =IF(OR(O9="",P9=""),"",(P9-O9)*100) | R9: =IF(OR(I9="",C9="",C9=0),"",I9/C9) | S9: =IF(OR(J9="",D9="",D9=0),"",J9/D9) | T9: =IF(OR(R9="",S9=""),"",(S9-R9)*100)
A10: Organic | B10: Total | C10: =SUMIFS(Totals!$D$5:$D$49,Totals!$A$5:$A$49,"All landing pages",Totals!$B$5:$B$49,"Organic",Totals!$C$5:$C$49,"Total") | D10: =SUMIFS(Totals!$E$5:$E$49,Totals!$A$5:$A$49,"All landing pages",Totals!$B$5:$B$49,"Organic",Totals!$C$5:$C$49,"Total") | E10: =IF(OR(C10="",D10="",D10=0,C10=0),"",D10/C10-1) | F10: =SUMIFS(Totals!$O$5:$O$49,Totals!$A$5:$A$49,"All landing pages",Totals!$B$5:$B$49,"Organic",Totals!$C$5:$C$49,"Total") | G10: =SUMIFS(Totals!$P$5:$P$49,Totals!$A$5:$A$49,"All landing pages",Totals!$B$5:$B$49,"Organic",Totals!$C$5:$C$49,"Total") | H10: =IF(OR(F10="",G10="",G10=0,F10=0),"",G10/F10-1) | I10: =SUMIFS(Totals!$AQ$5:$AQ$49,Totals!$A$5:$A$49,"All landing pages",Totals!$B$5:$B$49,"Organic",Totals!$C$5:$C$49,"Total") | J10: =SUMIFS(Totals!$AR$5:$AR$49,Totals!$A$5:$A$49,"All landing pages",Totals!$B$5:$B$49,"Organic",Totals!$C$5:$C$49,"Total") | K10: =IF(OR(I10="",J10="",J10=0,I10=0),"",J10/I10-1) | L10: =IF(OR(F10="",C10="",C10=0),"",F10/C10) | M10: =IF(OR(G10="",D10="",D10=0),"",G10/D10) | N10: =IF(OR(L10="",M10=""),"",(M10-L10)*100) | O10: =IF(OR(I10="",F10="",F10=0),"",I10/F10) | P10: =IF(OR(J10="",G10="",G10=0),"",J10/G10) | Q10: =IF(OR(O10="",P10=""),"",(P10-O10)*100) | R10: =IF(OR(I10="",C10="",C10=0),"",I10/C10) | S10: =IF(OR(J10="",D10="",D10=0),"",J10/D10) | T10: =IF(OR(R10="",S10=""),"",(S10-R10)*100)
A11: Direct | B11: Total | C11: =SUMIFS(Totals!$D$5:$D$49,Totals!$A$5:$A$49,"All landing pages",Totals!$B$5:$B$49,"Direct",Totals!$C$5:$C$49,"Total") | D11: =SUMIFS(Totals!$E$5:$E$49,Totals!$A$5:$A$49,"All landing pages",Totals!$B$5:$B$49,"Direct",Totals!$C$5:$C$49,"Total") | E11: =IF(OR(C11="",D11="",D11=0,C11=0),"",D11/C11-1) | F11: =SUMIFS(Totals!$O$5:$O$49,Totals!$A$5:$A$49,"All landing pages",Totals!$B$5:$B$49,"Direct",Totals!$C$5:$C$49,"Total") | G11: =SUMIFS(Totals!$P$5:$P$49,Totals!$A$5:$A$49,"All landing pages",Totals!$B$5:$B$49,"Direct",Totals!$C$5:$C$49,"Total") | H11: =IF(OR(F11="",G11="",G11=0,F11=0),"",G11/F11-1) | I11: =SUMIFS(Totals!$AQ$5:$AQ$49,Totals!$A$5:$A$49,"All landing pages",Totals!$B$5:$B$49,"Direct",Totals!$C$5:$C$49,"Total") | J11: =SUMIFS(Totals!$AR$5:$AR$49,Totals!$A$5:$A$49,"All landing pages",Totals!$B$5:$B$49,"Direct",Totals!$C$5:$C$49,"Total") | K11: =IF(OR(I11="",J11="",J11=0,I11=0),"",J11/I11-1) | L11: =IF(OR(F11="",C11="",C11=0),"",F11/C11) | M11: =IF(OR(G11="",D11="",D11=0),"",G11/D11) | N11: =IF(OR(L11="",M11=""),"",(M11-L11)*100) | O11: =IF(OR(I11="",F11="",F11=0),"",I11/F11) | P11: =IF(OR(J11="",G11="",G11=0),"",J11/G11) | Q11: =IF(OR(O11="",P11=""),"",(P11-O11)*100) | R11: =IF(OR(I11="",C11="",C11=0),"",I11/C11) | S11: =IF(OR(J11="",D11="",D11=0),"",J11/D11) | T11: =IF(OR(R11="",S11=""),"",(S11-R11)*100)
A13: By landing page group (3 channels combined, all devices)
A14: All landing pages | B14: Total | C14: =SUMIFS(Totals!$D$5:$D$49,Totals!$A$5:$A$49,"All landing pages",Totals!$B$5:$B$49,"Paid Search",Totals!$C$5:$C$49,"Total")+SUMIFS(Totals!$D$5:$D$49,Totals!$A$5:$A$49,"All landing pages",Totals!$B$5:$B$49,"Organic",Totals!$C$5:$C$49,"Total")+SUMIFS(Totals!$D$5:$D$49,Totals!$A$5:$A$49,"All landing pages",Totals!$B$5:$B$49,"Direct",Totals!$C$5:$C$49,"Total") | D14: =SUMIFS(Totals!$E$5:$E$49,Totals!$A$5:$A$49,"All landing pages",Totals!$B$5:$B$49,"Paid Search",Totals!$C$5:$C$49,"Total")+SUMIFS(Totals!$E$5:$E$49,Totals!$A$5:$A$49,"All landing pages",Totals!$B$5:$B$49,"Organic",Totals!$C$5:$C$49,"Total")+SUMIFS(Totals!$E$5:$E$49,Totals!$A$5:$A$49,"All landing pages",Totals!$B$5:$B$49,"Direct",Totals!$C$5:$C$49,"Total") | E14: =IF(OR(C14="",D14="",D14=0,C14=0),"",D14/C14-1) | F14: =SUMIFS(Totals!$O$5:$O$49,Totals!$A$5:$A$49,"All landing pages",Totals!$B$5:$B$49,"Paid Search",Totals!$C$5:$C$49,"Total")+SUMIFS(Totals!$O$5:$O$49,Totals!$A$5:$A$49,"All landing pages",Totals!$B$5:$B$49,"Organic",Totals!$C$5:$C$49,"Total")+SUMIFS(Totals!$O$5:$O$49,Totals!$A$5:$A$49,"All landing pages",Totals!$B$5:$B$49,"Direct",Totals!$C$5:$C$49,"Total") | G14: =SUMIFS(Totals!$P$5:$P$49,Totals!$A$5:$A$49,"All landing pages",Totals!$B$5:$B$49,"Paid Search",Totals!$C$5:$C$49,"Total")+SUMIFS(Totals!$P$5:$P$49,Totals!$A$5:$A$49,"All landing pages",Totals!$B$5:$B$49,"Organic",Totals!$C$5:$C$49,"Total")+SUMIFS(Totals!$P$5:$P$49,Totals!$A$5:$A$49,"All landing pages",Totals!$B$5:$B$49,"Direct",Totals!$C$5:$C$49,"Total") | H14: =IF(OR(F14="",G14="",G14=0,F14=0),"",G14/F14-1) | I14: =SUMIFS(Totals!$AQ$5:$AQ$49,Totals!$A$5:$A$49,"All landing pages",Totals!$B$5:$B$49,"Paid Search",Totals!$C$5:$C$49,"Total")+SUMIFS(Totals!$AQ$5:$AQ$49,Totals!$A$5:$A$49,"All landing pages",Totals!$B$5:$B$49,"Organic",Totals!$C$5:$C$49,"Total")+SUMIFS(Totals!$AQ$5:$AQ$49,Totals!$A$5:$A$49,"All landing pages",Totals!$B$5:$B$49,"Direct",Totals!$C$5:$C$49,"Total") | J14: =SUMIFS(Totals!$AR$5:$AR$49,Totals!$A$5:$A$49,"All landing pages",Totals!$B$5:$B$49,"Paid Search",Totals!$C$5:$C$49,"Total")+SUMIFS(Totals!$AR$5:$AR$49,Totals!$A$5:$A$49,"All landing pages",Totals!$B$5:$B$49,"Organic",Totals!$C$5:$C$49,"Total")+SUMIFS(Totals!$AR$5:$AR$49,Totals!$A$5:$A$49,"All landing pages",Totals!$B$5:$B$49,"Direct",Totals!$C$5:$C$49,"Total") | K14: =IF(OR(I14="",J14="",J14=0,I14=0),"",J14/I14-1) | L14: =IF(OR(F14="",C14="",C14=0),"",F14/C14) | M14: =IF(OR(G14="",D14="",D14=0),"",G14/D14) | N14: =IF(OR(L14="",M14=""),"",(M14-L14)*100) | O14: =IF(OR(I14="",F14="",F14=0),"",I14/F14) | P14: =IF(OR(J14="",G14="",G14=0),"",J14/G14) | Q14: =IF(OR(O14="",P14=""),"",(P14-O14)*100) | R14: =IF(OR(I14="",C14="",C14=0),"",I14/C14) | S14: =IF(OR(J14="",D14="",D14=0),"",J14/D14) | T14: =IF(OR(R14="",S14=""),"",(S14-R14)*100)
A15: Home page | B15: Total | C15: =SUMIFS(Totals!$D$5:$D$49,Totals!$A$5:$A$49,"Home page",Totals!$B$5:$B$49,"Paid Search",Totals!$C$5:$C$49,"Total")+SUMIFS(Totals!$D$5:$D$49,Totals!$A$5:$A$49,"Home page",Totals!$B$5:$B$49,"Organic",Totals!$C$5:$C$49,"Total")+SUMIFS(Totals!$D$5:$D$49,Totals!$A$5:$A$49,"Home page",Totals!$B$5:$B$49,"Direct",Totals!$C$5:$C$49,"Total") | D15: =SUMIFS(Totals!$E$5:$E$49,Totals!$A$5:$A$49,"Home page",Totals!$B$5:$B$49,"Paid Search",Totals!$C$5:$C$49,"Total")+SUMIFS(Totals!$E$5:$E$49,Totals!$A$5:$A$49,"Home page",Totals!$B$5:$B$49,"Organic",Totals!$C$5:$C$49,"Total")+SUMIFS(Totals!$E$5:$E$49,Totals!$A$5:$A$49,"Home page",Totals!$B$5:$B$49,"Direct",Totals!$C$5:$C$49,"Total") | E15: =IF(OR(C15="",D15="",D15=0,C15=0),"",D15/C15-1) | F15: =SUMIFS(Totals!$O$5:$O$49,Totals!$A$5:$A$49,"Home page",Totals!$B$5:$B$49,"Paid Search",Totals!$C$5:$C$49,"Total")+SUMIFS(Totals!$O$5:$O$49,Totals!$A$5:$A$49,"Home page",Totals!$B$5:$B$49,"Organic",Totals!$C$5:$C$49,"Total")+SUMIFS(Totals!$O$5:$O$49,Totals!$A$5:$A$49,"Home page",Totals!$B$5:$B$49,"Direct",Totals!$C$5:$C$49,"Total") | G15: =SUMIFS(Totals!$P$5:$P$49,Totals!$A$5:$A$49,"Home page",Totals!$B$5:$B$49,"Paid Search",Totals!$C$5:$C$49,"Total")+SUMIFS(Totals!$P$5:$P$49,Totals!$A$5:$A$49,"Home page",Totals!$B$5:$B$49,"Organic",Totals!$C$5:$C$49,"Total")+SUMIFS(Totals!$P$5:$P$49,Totals!$A$5:$A$49,"Home page",Totals!$B$5:$B$49,"Direct",Totals!$C$5:$C$49,"Total") | H15: =IF(OR(F15="",G15="",G15=0,F15=0),"",G15/F15-1) | I15: =SUMIFS(Totals!$AQ$5:$AQ$49,Totals!$A$5:$A$49,"Home page",Totals!$B$5:$B$49,"Paid Search",Totals!$C$5:$C$49,"Total")+SUMIFS(Totals!$AQ$5:$AQ$49,Totals!$A$5:$A$49,"Home page",Totals!$B$5:$B$49,"Organic",Totals!$C$5:$C$49,"Total")+SUMIFS(Totals!$AQ$5:$AQ$49,Totals!$A$5:$A$49,"Home page",Totals!$B$5:$B$49,"Direct",Totals!$C$5:$C$49,"Total") | J15: =SUMIFS(Totals!$AR$5:$AR$49,Totals!$A$5:$A$49,"Home page",Totals!$B$5:$B$49,"Paid Search",Totals!$C$5:$C$49,"Total")+SUMIFS(Totals!$AR$5:$AR$49,Totals!$A$5:$A$49,"Home page",Totals!$B$5:$B$49,"Organic",Totals!$C$5:$C$49,"Total")+SUMIFS(Totals!$AR$5:$AR$49,Totals!$A$5:$A$49,"Home page",Totals!$B$5:$B$49,"Direct",Totals!$C$5:$C$49,"Total") | K15: =IF(OR(I15="",J15="",J15=0,I15=0),"",J15/I15-1) | L15: =IF(OR(F15="",C15="",C15=0),"",F15/C15) | M15: =IF(OR(G15="",D15="",D15=0),"",G15/D15) | N15: =IF(OR(L15="",M15=""),"",(M15-L15)*100) | O15: =IF(OR(I15="",F15="",F15=0),"",I15/F15) | P15: =IF(OR(J15="",G15="",G15=0),"",J15/G15) | Q15: =IF(OR(O15="",P15=""),"",(P15-O15)*100) | R15: =IF(OR(I15="",C15="",C15=0),"",I15/C15) | S15: =IF(OR(J15="",D15="",D15=0),"",J15/D15) | T15: =IF(OR(R15="",S15=""),"",(S15-R15)*100)
A16: Airport page | B16: Total | C16: =SUMIFS(Totals!$D$5:$D$49,Totals!$A$5:$A$49,"Airport page",Totals!$B$5:$B$49,"Paid Search",Totals!$C$5:$C$49,"Total")+SUMIFS(Totals!$D$5:$D$49,Totals!$A$5:$A$49,"Airport page",Totals!$B$5:$B$49,"Organic",Totals!$C$5:$C$49,"Total")+SUMIFS(Totals!$D$5:$D$49,Totals!$A$5:$A$49,"Airport page",Totals!$B$5:$B$49,"Direct",Totals!$C$5:$C$49,"Total") | D16: =SUMIFS(Totals!$E$5:$E$49,Totals!$A$5:$A$49,"Airport page",Totals!$B$5:$B$49,"Paid Search",Totals!$C$5:$C$49,"Total")+SUMIFS(Totals!$E$5:$E$49,Totals!$A$5:$A$49,"Airport page",Totals!$B$5:$B$49,"Organic",Totals!$C$5:$C$49,"Total")+SUMIFS(Totals!$E$5:$E$49,Totals!$A$5:$A$49,"Airport page",Totals!$B$5:$B$49,"Direct",Totals!$C$5:$C$49,"Total") | E16: =IF(OR(C16="",D16="",D16=0,C16=0),"",D16/C16-1) | F16: =SUMIFS(Totals!$O$5:$O$49,Totals!$A$5:$A$49,"Airport page",Totals!$B$5:$B$49,"Paid Search",Totals!$C$5:$C$49,"Total")+SUMIFS(Totals!$O$5:$O$49,Totals!$A$5:$A$49,"Airport page",Totals!$B$5:$B$49,"Organic",Totals!$C$5:$C$49,"Total")+SUMIFS(Totals!$O$5:$O$49,Totals!$A$5:$A$49,"Airport page",Totals!$B$5:$B$49,"Direct",Totals!$C$5:$C$49,"Total") | G16: =SUMIFS(Totals!$P$5:$P$49,Totals!$A$5:$A$49,"Airport page",Totals!$B$5:$B$49,"Paid Search",Totals!$C$5:$C$49,"Total")+SUMIFS(Totals!$P$5:$P$49,Totals!$A$5:$A$49,"Airport page",Totals!$B$5:$B$49,"Organic",Totals!$C$5:$C$49,"Total")+SUMIFS(Totals!$P$5:$P$49,Totals!$A$5:$A$49,"Airport page",Totals!$B$5:$B$49,"Direct",Totals!$C$5:$C$49,"Total") | H16: =IF(OR(F16="",G16="",G16=0,F16=0),"",G16/F16-1) | I16: =SUMIFS(Totals!$AQ$5:$AQ$49,Totals!$A$5:$A$49,"Airport page",Totals!$B$5:$B$49,"Paid Search",Totals!$C$5:$C$49,"Total")+SUMIFS(Totals!$AQ$5:$AQ$49,Totals!$A$5:$A$49,"Airport page",Totals!$B$5:$B$49,"Organic",Totals!$C$5:$C$49,"Total")+SUMIFS(Totals!$AQ$5:$AQ$49,Totals!$A$5:$A$49,"Airport page",Totals!$B$5:$B$49,"Direct",Totals!$C$5:$C$49,"Total") | J16: =SUMIFS(Totals!$AR$5:$AR$49,Totals!$A$5:$A$49,"Airport page",Totals!$B$5:$B$49,"Paid Search",Totals!$C$5:$C$49,"Total")+SUMIFS(Totals!$AR$5:$AR$49,Totals!$A$5:$A$49,"Airport page",Totals!$B$5:$B$49,"Organic",Totals!$C$5:$C$49,"Total")+SUMIFS(Totals!$AR$5:$AR$49,Totals!$A$5:$A$49,"Airport page",Totals!$B$5:$B$49,"Direct",Totals!$C$5:$C$49,"Total") | K16: =IF(OR(I16="",J16="",J16=0,I16=0),"",J16/I16-1) | L16: =IF(OR(F16="",C16="",C16=0),"",F16/C16) | M16: =IF(OR(G16="",D16="",D16=0),"",G16/D16) | N16: =IF(OR(L16="",M16=""),"",(M16-L16)*100) | O16: =IF(OR(I16="",F16="",F16=0),"",I16/F16) | P16: =IF(OR(J16="",G16="",G16=0),"",J16/G16) | Q16: =IF(OR(O16="",P16=""),"",(P16-O16)*100) | R16: =IF(OR(I16="",C16="",C16=0),"",I16/C16) | S16: =IF(OR(J16="",D16="",D16=0),"",J16/D16) | T16: =IF(OR(R16="",S16=""),"",(S16-R16)*100)
A17: Route page | B17: Total | C17: =SUMIFS(Totals!$D$5:$D$49,Totals!$A$5:$A$49,"Route page",Totals!$B$5:$B$49,"Paid Search",Totals!$C$5:$C$49,"Total")+SUMIFS(Totals!$D$5:$D$49,Totals!$A$5:$A$49,"Route page",Totals!$B$5:$B$49,"Organic",Totals!$C$5:$C$49,"Total")+SUMIFS(Totals!$D$5:$D$49,Totals!$A$5:$A$49,"Route page",Totals!$B$5:$B$49,"Direct",Totals!$C$5:$C$49,"Total") | D17: =SUMIFS(Totals!$E$5:$E$49,Totals!$A$5:$A$49,"Route page",Totals!$B$5:$B$49,"Paid Search",Totals!$C$5:$C$49,"Total")+SUMIFS(Totals!$E$5:$E$49,Totals!$A$5:$A$49,"Route page",Totals!$B$5:$B$49,"Organic",Totals!$C$5:$C$49,"Total")+SUMIFS(Totals!$E$5:$E$49,Totals!$A$5:$A$49,"Route page",Totals!$B$5:$B$49,"Direct",Totals!$C$5:$C$49,"Total") | E17: =IF(OR(C17="",D17="",D17=0,C17=0),"",D17/C17-1) | F17: =SUMIFS(Totals!$O$5:$O$49,Totals!$A$5:$A$49,"Route page",Totals!$B$5:$B$49,"Paid Search",Totals!$C$5:$C$49,"Total")+SUMIFS(Totals!$O$5:$O$49,Totals!$A$5:$A$49,"Route page",Totals!$B$5:$B$49,"Organic",Totals!$C$5:$C$49,"Total")+SUMIFS(Totals!$O$5:$O$49,Totals!$A$5:$A$49,"Route page",Totals!$B$5:$B$49,"Direct",Totals!$C$5:$C$49,"Total") | G17: =SUMIFS(Totals!$P$5:$P$49,Totals!$A$5:$A$49,"Route page",Totals!$B$5:$B$49,"Paid Search",Totals!$C$5:$C$49,"Total")+SUMIFS(Totals!$P$5:$P$49,Totals!$A$5:$A$49,"Route page",Totals!$B$5:$B$49,"Organic",Totals!$C$5:$C$49,"Total")+SUMIFS(Totals!$P$5:$P$49,Totals!$A$5:$A$49,"Route page",Totals!$B$5:$B$49,"Direct",Totals!$C$5:$C$49,"Total") | H17: =IF(OR(F17="",G17="",G17=0,F17=0),"",G17/F17-1) | I17: =SUMIFS(Totals!$AQ$5:$AQ$49,Totals!$A$5:$A$49,"Route page",Totals!$B$5:$B$49,"Paid Search",Totals!$C$5:$C$49,"Total")+SUMIFS(Totals!$AQ$5:$AQ$49,Totals!$A$5:$A$49,"Route page",Totals!$B$5:$B$49,"Organic",Totals!$C$5:$C$49,"Total")+SUMIFS(Totals!$AQ$5:$AQ$49,Totals!$A$5:$A$49,"Route page",Totals!$B$5:$B$49,"Direct",Totals!$C$5:$C$49,"Total") | J17: =SUMIFS(Totals!$AR$5:$AR$49,Totals!$A$5:$A$49,"Route page",Totals!$B$5:$B$49,"Paid Search",Totals!$C$5:$C$49,"Total")+SUMIFS(Totals!$AR$5:$AR$49,Totals!$A$5:$A$49,"Route page",Totals!$B$5:$B$49,"Organic",Totals!$C$5:$C$49,"Total")+SUMIFS(Totals!$AR$5:$AR$49,Totals!$A$5:$A$49,"Route page",Totals!$B$5:$B$49,"Direct",Totals!$C$5:$C$49,"Total") | K17: =IF(OR(I17="",J17="",J17=0,I17=0),"",J17/I17-1) | L17: =IF(OR(F17="",C17="",C17=0),"",F17/C17) | M17: =IF(OR(G17="",D17="",D17=0),"",G17/D17) | N17: =IF(OR(L17="",M17=""),"",(M17-L17)*100) | O17: =IF(OR(I17="",F17="",F17=0),"",I17/F17) | P17: =IF(OR(J17="",G17="",G17=0),"",J17/G17) | Q17: =IF(OR(O17="",P17=""),"",(P17-O17)*100) | R17: =IF(OR(I17="",C17="",C17=0),"",I17/C17) | S17: =IF(OR(J17="",D17="",D17=0),"",J17/D17) | T17: =IF(OR(R17="",S17=""),"",(S17-R17)*100)
A18: Other pages (derived) | B18: Total | C18: =SUMIFS(Totals!$D$5:$D$49,Totals!$A$5:$A$49,"Other pages (derived)",Totals!$B$5:$B$49,"Paid Search",Totals!$C$5:$C$49,"Total")+SUMIFS(Totals!$D$5:$D$49,Totals!$A$5:$A$49,"Other pages (derived)",Totals!$B$5:$B$49,"Organic",Totals!$C$5:$C$49,"Total")+SUMIFS(Totals!$D$5:$D$49,Totals!$A$5:$A$49,"Other pages (derived)",Totals!$B$5:$B$49,"Direct",Totals!$C$5:$C$49,"Total") | D18: =SUMIFS(Totals!$E$5:$E$49,Totals!$A$5:$A$49,"Other pages (derived)",Totals!$B$5:$B$49,"Paid Search",Totals!$C$5:$C$49,"Total")+SUMIFS(Totals!$E$5:$E$49,Totals!$A$5:$A$49,"Other pages (derived)",Totals!$B$5:$B$49,"Organic",Totals!$C$5:$C$49,"Total")+SUMIFS(Totals!$E$5:$E$49,Totals!$A$5:$A$49,"Other pages (derived)",Totals!$B$5:$B$49,"Direct",Totals!$C$5:$C$49,"Total") | E18: =IF(OR(C18="",D18="",D18=0,C18=0),"",D18/C18-1) | F18: =SUMIFS(Totals!$O$5:$O$49,Totals!$A$5:$A$49,"Other pages (derived)",Totals!$B$5:$B$49,"Paid Search",Totals!$C$5:$C$49,"Total")+SUMIFS(Totals!$O$5:$O$49,Totals!$A$5:$A$49,"Other pages (derived)",Totals!$B$5:$B$49,"Organic",Totals!$C$5:$C$49,"Total")+SUMIFS(Totals!$O$5:$O$49,Totals!$A$5:$A$49,"Other pages (derived)",Totals!$B$5:$B$49,"Direct",Totals!$C$5:$C$49,"Total") | G18: =SUMIFS(Totals!$P$5:$P$49,Totals!$A$5:$A$49,"Other pages (derived)",Totals!$B$5:$B$49,"Paid Search",Totals!$C$5:$C$49,"Total")+SUMIFS(Totals!$P$5:$P$49,Totals!$A$5:$A$49,"Other pages (derived)",Totals!$B$5:$B$49,"Organic",Totals!$C$5:$C$49,"Total")+SUMIFS(Totals!$P$5:$P$49,Totals!$A$5:$A$49,"Other pages (derived)",Totals!$B$5:$B$49,"Direct",Totals!$C$5:$C$49,"Total") | H18: =IF(OR(F18="",G18="",G18=0,F18=0),"",G18/F18-1) | I18: =SUMIFS(Totals!$AQ$5:$AQ$49,Totals!$A$5:$A$49,"Other pages (derived)",Totals!$B$5:$B$49,"Paid Search",Totals!$C$5:$C$49,"Total")+SUMIFS(Totals!$AQ$5:$AQ$49,Totals!$A$5:$A$49,"Other pages (derived)",Totals!$B$5:$B$49,"Organic",Totals!$C$5:$C$49,"Total")+SUMIFS(Totals!$AQ$5:$AQ$49,Totals!$A$5:$A$49,"Other pages (derived)",Totals!$B$5:$B$49,"Direct",Totals!$C$5:$C$49,"Total") | J18: =SUMIFS(Totals!$AR$5:$AR$49,Totals!$A$5:$A$49,"Other pages (derived)",Totals!$B$5:$B$49,"Paid Search",Totals!$C$5:$C$49,"Total")+SUMIFS(Totals!$AR$5:$AR$49,Totals!$A$5:$A$49,"Other pages (derived)",Totals!$B$5:$B$49,"Organic",Totals!$C$5:$C$49,"Total")+SUMIFS(Totals!$AR$5:$AR$49,Totals!$A$5:$A$49,"Other pages (derived)",Totals!$B$5:$B$49,"Direct",Totals!$C$5:$C$49,"Total") | K18: =IF(OR(I18="",J18="",J18=0,I18=0),"",J18/I18-1) | L18: =IF(OR(F18="",C18="",C18=0),"",F18/C18) | M18: =IF(OR(G18="",D18="",D18=0),"",G18/D18) | N18: =IF(OR(L18="",M18=""),"",(M18-L18)*100) | O18: =IF(OR(I18="",F18="",F18=0),"",I18/F18) | P18: =IF(OR(J18="",G18="",G18=0),"",J18/G18) | Q18: =IF(OR(O18="",P18=""),"",(P18-O18)*100) | R18: =IF(OR(I18="",C18="",C18=0),"",I18/C18) | S18: =IF(OR(J18="",D18="",D18=0),"",J18/D18) | T18: =IF(OR(R18="",S18=""),"",(S18-R18)*100)
A20: By device (3 channels combined, all landing pages)
A21: All traffic | B21: Total | C21: =SUMIFS(Totals!$D$5:$D$49,Totals!$A$5:$A$49,"All landing pages",Totals!$B$5:$B$49,"Paid Search",Totals!$C$5:$C$49,"Total")+SUMIFS(Totals!$D$5:$D$49,Totals!$A$5:$A$49,"All landing pages",Totals!$B$5:$B$49,"Organic",Totals!$C$5:$C$49,"Total")+SUMIFS(Totals!$D$5:$D$49,Totals!$A$5:$A$49,"All landing pages",Totals!$B$5:$B$49,"Direct",Totals!$C$5:$C$49,"Total") | D21: =SUMIFS(Totals!$E$5:$E$49,Totals!$A$5:$A$49,"All landing pages",Totals!$B$5:$B$49,"Paid Search",Totals!$C$5:$C$49,"Total")+SUMIFS(Totals!$E$5:$E$49,Totals!$A$5:$A$49,"All landing pages",Totals!$B$5:$B$49,"Organic",Totals!$C$5:$C$49,"Total")+SUMIFS(Totals!$E$5:$E$49,Totals!$A$5:$A$49,"All landing pages",Totals!$B$5:$B$49,"Direct",Totals!$C$5:$C$49,"Total") | E21: =IF(OR(C21="",D21="",D21=0,C21=0),"",D21/C21-1) | F21: =SUMIFS(Totals!$O$5:$O$49,Totals!$A$5:$A$49,"All landing pages",Totals!$B$5:$B$49,"Paid Search",Totals!$C$5:$C$49,"Total")+SUMIFS(Totals!$O$5:$O$49,Totals!$A$5:$A$49,"All landing pages",Totals!$B$5:$B$49,"Organic",Totals!$C$5:$C$49,"Total")+SUMIFS(Totals!$O$5:$O$49,Totals!$A$5:$A$49,"All landing pages",Totals!$B$5:$B$49,"Direct",Totals!$C$5:$C$49,"Total") | G21: =SUMIFS(Totals!$P$5:$P$49,Totals!$A$5:$A$49,"All landing pages",Totals!$B$5:$B$49,"Paid Search",Totals!$C$5:$C$49,"Total")+SUMIFS(Totals!$P$5:$P$49,Totals!$A$5:$A$49,"All landing pages",Totals!$B$5:$B$49,"Organic",Totals!$C$5:$C$49,"Total")+SUMIFS(Totals!$P$5:$P$49,Totals!$A$5:$A$49,"All landing pages",Totals!$B$5:$B$49,"Direct",Totals!$C$5:$C$49,"Total") | H21: =IF(OR(F21="",G21="",G21=0,F21=0),"",G21/F21-1) | I21: =SUMIFS(Totals!$AQ$5:$AQ$49,Totals!$A$5:$A$49,"All landing pages",Totals!$B$5:$B$49,"Paid Search",Totals!$C$5:$C$49,"Total")+SUMIFS(Totals!$AQ$5:$AQ$49,Totals!$A$5:$A$49,"All landing pages",Totals!$B$5:$B$49,"Organic",Totals!$C$5:$C$49,"Total")+SUMIFS(Totals!$AQ$5:$AQ$49,Totals!$A$5:$A$49,"All landing pages",Totals!$B$5:$B$49,"Direct",Totals!$C$5:$C$49,"Total") | J21: =SUMIFS(Totals!$AR$5:$AR$49,Totals!$A$5:$A$49,"All landing pages",Totals!$B$5:$B$49,"Paid Search",Totals!$C$5:$C$49,"Total")+SUMIFS(Totals!$AR$5:$AR$49,Totals!$A$5:$A$49,"All landing pages",Totals!$B$5:$B$49,"Organic",Totals!$C$5:$C$49,"Total")+SUMIFS(Totals!$AR$5:$AR$49,Totals!$A$5:$A$49,"All landing pages",Totals!$B$5:$B$49,"Direct",Totals!$C$5:$C$49,"Total") | K21: =IF(OR(I21="",J21="",J21=0,I21=0),"",J21/I21-1) | L21: =IF(OR(F21="",C21="",C21=0),"",F21/C21) | M21: =IF(OR(G21="",D21="",D21=0),"",G21/D21) | N21: =IF(OR(L21="",M21=""),"",(M21-L21)*100) | O21: =IF(OR(I21="",F21="",F21=0),"",I21/F21) | P21: =IF(OR(J21="",G21="",G21=0),"",J21/G21) | Q21: =IF(OR(O21="",P21=""),"",(P21-O21)*100) | R21: =IF(OR(I21="",C21="",C21=0),"",I21/C21) | S21: =IF(OR(J21="",D21="",D21=0),"",J21/D21) | T21: =IF(OR(R21="",S21=""),"",(S21-R21)*100)
A22: All traffic | B22: Mobile | C22: =SUMIFS(Totals!$D$5:$D$49,Totals!$A$5:$A$49,"All landing pages",Totals!$B$5:$B$49,"Paid Search",Totals!$C$5:$C$49,"Mobile")+SUMIFS(Totals!$D$5:$D$49,Totals!$A$5:$A$49,"All landing pages",Totals!$B$5:$B$49,"Organic",Totals!$C$5:$C$49,"Mobile")+SUMIFS(Totals!$D$5:$D$49,Totals!$A$5:$A$49,"All landing pages",Totals!$B$5:$B$49,"Direct",Totals!$C$5:$C$49,"Mobile") | D22: =SUMIFS(Totals!$E$5:$E$49,Totals!$A$5:$A$49,"All landing pages",Totals!$B$5:$B$49,"Paid Search",Totals!$C$5:$C$49,"Mobile")+SUMIFS(Totals!$E$5:$E$49,Totals!$A$5:$A$49,"All landing pages",Totals!$B$5:$B$49,"Organic",Totals!$C$5:$C$49,"Mobile")+SUMIFS(Totals!$E$5:$E$49,Totals!$A$5:$A$49,"All landing pages",Totals!$B$5:$B$49,"Direct",Totals!$C$5:$C$49,"Mobile") | E22: =IF(OR(C22="",D22="",D22=0,C22=0),"",D22/C22-1) | F22: =SUMIFS(Totals!$O$5:$O$49,Totals!$A$5:$A$49,"All landing pages",Totals!$B$5:$B$49,"Paid Search",Totals!$C$5:$C$49,"Mobile")+SUMIFS(Totals!$O$5:$O$49,Totals!$A$5:$A$49,"All landing pages",Totals!$B$5:$B$49,"Organic",Totals!$C$5:$C$49,"Mobile")+SUMIFS(Totals!$O$5:$O$49,Totals!$A$5:$A$49,"All landing pages",Totals!$B$5:$B$49,"Direct",Totals!$C$5:$C$49,"Mobile") | G22: =SUMIFS(Totals!$P$5:$P$49,Totals!$A$5:$A$49,"All landing pages",Totals!$B$5:$B$49,"Paid Search",Totals!$C$5:$C$49,"Mobile")+SUMIFS(Totals!$P$5:$P$49,Totals!$A$5:$A$49,"All landing pages",Totals!$B$5:$B$49,"Organic",Totals!$C$5:$C$49,"Mobile")+SUMIFS(Totals!$P$5:$P$49,Totals!$A$5:$A$49,"All landing pages",Totals!$B$5:$B$49,"Direct",Totals!$C$5:$C$49,"Mobile") | H22: =IF(OR(F22="",G22="",G22=0,F22=0),"",G22/F22-1) | I22: =SUMIFS(Totals!$AQ$5:$AQ$49,Totals!$A$5:$A$49,"All landing pages",Totals!$B$5:$B$49,"Paid Search",Totals!$C$5:$C$49,"Mobile")+SUMIFS(Totals!$AQ$5:$AQ$49,Totals!$A$5:$A$49,"All landing pages",Totals!$B$5:$B$49,"Organic",Totals!$C$5:$C$49,"Mobile")+SUMIFS(Totals!$AQ$5:$AQ$49,Totals!$A$5:$A$49,"All landing pages",Totals!$B$5:$B$49,"Direct",Totals!$C$5:$C$49,"Mobile") | J22: =SUMIFS(Totals!$AR$5:$AR$49,Totals!$A$5:$A$49,"All landing pages",Totals!$B$5:$B$49,"Paid Search",Totals!$C$5:$C$49,"Mobile")+SUMIFS(Totals!$AR$5:$AR$49,Totals!$A$5:$A$49,"All landing pages",Totals!$B$5:$B$49,"Organic",Totals!$C$5:$C$49,"Mobile")+SUMIFS(Totals!$AR$5:$AR$49,Totals!$A$5:$A$49,"All landing pages",Totals!$B$5:$B$49,"Direct",Totals!$C$5:$C$49,"Mobile") | K22: =IF(OR(I22="",J22="",J22=0,I22=0),"",J22/I22-1) | L22: =IF(OR(F22="",C22="",C22=0),"",F22/C22) | M22: =IF(OR(G22="",D22="",D22=0),"",G22/D22) | N22: =IF(OR(L22="",M22=""),"",(M22-L22)*100) | O22: =IF(OR(I22="",F22="",F22=0),"",I22/F22) | P22: =IF(OR(J22="",G22="",G22=0),"",J22/G22) | Q22: =IF(OR(O22="",P22=""),"",(P22-O22)*100) | R22: =IF(OR(I22="",C22="",C22=0),"",I22/C22) | S22: =IF(OR(J22="",D22="",D22=0),"",J22/D22) | T22: =IF(OR(R22="",S22=""),"",(S22-R22)*100)
A23: All traffic | B23: Desktop | C23: =SUMIFS(Totals!$D$5:$D$49,Totals!$A$5:$A$49,"All landing pages",Totals!$B$5:$B$49,"Paid Search",Totals!$C$5:$C$49,"Desktop")+SUMIFS(Totals!$D$5:$D$49,Totals!$A$5:$A$49,"All landing pages",Totals!$B$5:$B$49,"Organic",Totals!$C$5:$C$49,"Desktop")+SUMIFS(Totals!$D$5:$D$49,Totals!$A$5:$A$49,"All landing pages",Totals!$B$5:$B$49,"Direct",Totals!$C$5:$C$49,"Desktop") | D23: =SUMIFS(Totals!$E$5:$E$49,Totals!$A$5:$A$49,"All landing pages",Totals!$B$5:$B$49,"Paid Search",Totals!$C$5:$C$49,"Desktop")+SUMIFS(Totals!$E$5:$E$49,Totals!$A$5:$A$49,"All landing pages",Totals!$B$5:$B$49,"Organic",Totals!$C$5:$C$49,"Desktop")+SUMIFS(Totals!$E$5:$E$49,Totals!$A$5:$A$49,"All landing pages",Totals!$B$5:$B$49,"Direct",Totals!$C$5:$C$49,"Desktop") | E23: =IF(OR(C23="",D23="",D23=0,C23=0),"",D23/C23-1) | F23: =SUMIFS(Totals!$O$5:$O$49,Totals!$A$5:$A$49,"All landing pages",Totals!$B$5:$B$49,"Paid Search",Totals!$C$5:$C$49,"Desktop")+SUMIFS(Totals!$O$5:$O$49,Totals!$A$5:$A$49,"All landing pages",Totals!$B$5:$B$49,"Organic",Totals!$C$5:$C$49,"Desktop")+SUMIFS(Totals!$O$5:$O$49,Totals!$A$5:$A$49,"All landing pages",Totals!$B$5:$B$49,"Direct",Totals!$C$5:$C$49,"Desktop") | G23: =SUMIFS(Totals!$P$5:$P$49,Totals!$A$5:$A$49,"All landing pages",Totals!$B$5:$B$49,"Paid Search",Totals!$C$5:$C$49,"Desktop")+SUMIFS(Totals!$P$5:$P$49,Totals!$A$5:$A$49,"All landing pages",Totals!$B$5:$B$49,"Organic",Totals!$C$5:$C$49,"Desktop")+SUMIFS(Totals!$P$5:$P$49,Totals!$A$5:$A$49,"All landing pages",Totals!$B$5:$B$49,"Direct",Totals!$C$5:$C$49,"Desktop") | H23: =IF(OR(F23="",G23="",G23=0,F23=0),"",G23/F23-1) | I23: =SUMIFS(Totals!$AQ$5:$AQ$49,Totals!$A$5:$A$49,"All landing pages",Totals!$B$5:$B$49,"Paid Search",Totals!$C$5:$C$49,"Desktop")+SUMIFS(Totals!$AQ$5:$AQ$49,Totals!$A$5:$A$49,"All landing pages",Totals!$B$5:$B$49,"Organic",Totals!$C$5:$C$49,"Desktop")+SUMIFS(Totals!$AQ$5:$AQ$49,Totals!$A$5:$A$49,"All landing pages",Totals!$B$5:$B$49,"Direct",Totals!$C$5:$C$49,"Desktop") | J23: =SUMIFS(Totals!$AR$5:$AR$49,Totals!$A$5:$A$49,"All landing pages",Totals!$B$5:$B$49,"Paid Search",Totals!$C$5:$C$49,"Desktop")+SUMIFS(Totals!$AR$5:$AR$49,Totals!$A$5:$A$49,"All landing pages",Totals!$B$5:$B$49,"Organic",Totals!$C$5:$C$49,"Desktop")+SUMIFS(Totals!$AR$5:$AR$49,Totals!$A$5:$A$49,"All landing pages",Totals!$B$5:$B$49,"Direct",Totals!$C$5:$C$49,"Desktop") | K23: =IF(OR(I23="",J23="",J23=0,I23=0),"",J23/I23-1) | L23: =IF(OR(F23="",C23="",C23=0),"",F23/C23) | M23: =IF(OR(G23="",D23="",D23=0),"",G23/D23) | N23: =IF(OR(L23="",M23=""),"",(M23-L23)*100) | O23: =IF(OR(I23="",F23="",F23=0),"",I23/F23) | P23: =IF(OR(J23="",G23="",G23=0),"",J23/G23) | Q23: =IF(OR(O23="",P23=""),"",(P23-O23)*100) | R23: =IF(OR(I23="",C23="",C23=0),"",I23/C23) | S23: =IF(OR(J23="",D23="",D23=0),"",J23/D23) | T23: =IF(OR(R23="",S23=""),"",(S23-R23)*100)
A25: By channel × device
A26: Paid Search | B26: Mobile | C26: =SUMIFS(Totals!$D$5:$D$49,Totals!$A$5:$A$49,"All landing pages",Totals!$B$5:$B$49,"Paid Search",Totals!$C$5:$C$49,"Mobile") | D26: =SUMIFS(Totals!$E$5:$E$49,Totals!$A$5:$A$49,"All landing pages",Totals!$B$5:$B$49,"Paid Search",Totals!$C$5:$C$49,"Mobile") | E26: =IF(OR(C26="",D26="",D26=0,C26=0),"",D26/C26-1) | F26: =SUMIFS(Totals!$O$5:$O$49,Totals!$A$5:$A$49,"All landing pages",Totals!$B$5:$B$49,"Paid Search",Totals!$C$5:$C$49,"Mobile") | G26: =SUMIFS(Totals!$P$5:$P$49,Totals!$A$5:$A$49,"All landing pages",Totals!$B$5:$B$49,"Paid Search",Totals!$C$5:$C$49,"Mobile") | H26: =IF(OR(F26="",G26="",G26=0,F26=0),"",G26/F26-1) | I26: =SUMIFS(Totals!$AQ$5:$AQ$49,Totals!$A$5:$A$49,"All landing pages",Totals!$B$5:$B$49,"Paid Search",Totals!$C$5:$C$49,"Mobile") | J26: =SUMIFS(Totals!$AR$5:$AR$49,Totals!$A$5:$A$49,"All landing pages",Totals!$B$5:$B$49,"Paid Search",Totals!$C$5:$C$49,"Mobile") | K26: =IF(OR(I26="",J26="",J26=0,I26=0),"",J26/I26-1) | L26: =IF(OR(F26="",C26="",C26=0),"",F26/C26) | M26: =IF(OR(G26="",D26="",D26=0),"",G26/D26) | N26: =IF(OR(L26="",M26=""),"",(M26-L26)*100) | O26: =IF(OR(I26="",F26="",F26=0),"",I26/F26) | P26: =IF(OR(J26="",G26="",G26=0),"",J26/G26) | Q26: =IF(OR(O26="",P26=""),"",(P26-O26)*100) | R26: =IF(OR(I26="",C26="",C26=0),"",I26/C26) | S26: =IF(OR(J26="",D26="",D26=0),"",J26/D26) | T26: =IF(OR(R26="",S26=""),"",(S26-R26)*100)
A27: Paid Search | B27: Desktop | C27: =SUMIFS(Totals!$D$5:$D$49,Totals!$A$5:$A$49,"All landing pages",Totals!$B$5:$B$49,"Paid Search",Totals!$C$5:$C$49,"Desktop") | D27: =SUMIFS(Totals!$E$5:$E$49,Totals!$A$5:$A$49,"All landing pages",Totals!$B$5:$B$49,"Paid Search",Totals!$C$5:$C$49,"Desktop") | E27: =IF(OR(C27="",D27="",D27=0,C27=0),"",D27/C27-1) | F27: =SUMIFS(Totals!$O$5:$O$49,Totals!$A$5:$A$49,"All landing pages",Totals!$B$5:$B$49,"Paid Search",Totals!$C$5:$C$49,"Desktop") | G27: =SUMIFS(Totals!$P$5:$P$49,Totals!$A$5:$A$49,"All landing pages",Totals!$B$5:$B$49,"Paid Search",Totals!$C$5:$C$49,"Desktop") | H27: =IF(OR(F27="",G27="",G27=0,F27=0),"",G27/F27-1) | I27: =SUMIFS(Totals!$AQ$5:$AQ$49,Totals!$A$5:$A$49,"All landing pages",Totals!$B$5:$B$49,"Paid Search",Totals!$C$5:$C$49,"Desktop") | J27: =SUMIFS(Totals!$AR$5:$AR$49,Totals!$A$5:$A$49,"All landing pages",Totals!$B$5:$B$49,"Paid Search",Totals!$C$5:$C$49,"Desktop") | K27: =IF(OR(I27="",J27="",J27=0,I27=0),"",J27/I27-1) | L27: =IF(OR(F27="",C27="",C27=0),"",F27/C27) | M27: =IF(OR(G27="",D27="",D27=0),"",G27/D27) | N27: =IF(OR(L27="",M27=""),"",(M27-L27)*100) | O27: =IF(OR(I27="",F27="",F27=0),"",I27/F27) | P27: =IF(OR(J27="",G27="",G27=0),"",J27/G27) | Q27: =IF(OR(O27="",P27=""),"",(P27-O27)*100) | R27: =IF(OR(I27="",C27="",C27=0),"",I27/C27) | S27: =IF(OR(J27="",D27="",D27=0),"",J27/D27) | T27: =IF(OR(R27="",S27=""),"",(S27-R27)*100)
A28: Organic | B28: Mobile | C28: =SUMIFS(Totals!$D$5:$D$49,Totals!$A$5:$A$49,"All landing pages",Totals!$B$5:$B$49,"Organic",Totals!$C$5:$C$49,"Mobile") | D28: =SUMIFS(Totals!$E$5:$E$49,Totals!$A$5:$A$49,"All landing pages",Totals!$B$5:$B$49,"Organic",Totals!$C$5:$C$49,"Mobile") | E28: =IF(OR(C28="",D28="",D28=0,C28=0),"",D28/C28-1) | F28: =SUMIFS(Totals!$O$5:$O$49,Totals!$A$5:$A$49,"All landing pages",Totals!$B$5:$B$49,"Organic",Totals!$C$5:$C$49,"Mobile") | G28: =SUMIFS(Totals!$P$5:$P$49,Totals!$A$5:$A$49,"All landing pages",Totals!$B$5:$B$49,"Organic",Totals!$C$5:$C$49,"Mobile") | H28: =IF(OR(F28="",G28="",G28=0,F28=0),"",G28/F28-1) | I28: =SUMIFS(Totals!$AQ$5:$AQ$49,Totals!$A$5:$A$49,"All landing pages",Totals!$B$5:$B$49,"Organic",Totals!$C$5:$C$49,"Mobile") | J28: =SUMIFS(Totals!$AR$5:$AR$49,Totals!$A$5:$A$49,"All landing pages",Totals!$B$5:$B$49,"Organic",Totals!$C$5:$C$49,"Mobile") | K28: =IF(OR(I28="",J28="",J28=0,I28=0),"",J28/I28-1) | L28: =IF(OR(F28="",C28="",C28=0),"",F28/C28) | M28: =IF(OR(G28="",D28="",D28=0),"",G28/D28) | N28: =IF(OR(L28="",M28=""),"",(M28-L28)*100) | O28: =IF(OR(I28="",F28="",F28=0),"",I28/F28) | P28: =IF(OR(J28="",G28="",G28=0),"",J28/G28) | Q28: =IF(OR(O28="",P28=""),"",(P28-O28)*100) | R28: =IF(OR(I28="",C28="",C28=0),"",I28/C28) | S28: =IF(OR(J28="",D28="",D28=0),"",J28/D28) | T28: =IF(OR(R28="",S28=""),"",(S28-R28)*100)
A29: Organic | B29: Desktop | C29: =SUMIFS(Totals!$D$5:$D$49,Totals!$A$5:$A$49,"All landing pages",Totals!$B$5:$B$49,"Organic",Totals!$C$5:$C$49,"Desktop") | D29: =SUMIFS(Totals!$E$5:$E$49,Totals!$A$5:$A$49,"All landing pages",Totals!$B$5:$B$49,"Organic",Totals!$C$5:$C$49,"Desktop") | E29: =IF(OR(C29="",D29="",D29=0,C29=0),"",D29/C29-1) | F29: =SUMIFS(Totals!$O$5:$O$49,Totals!$A$5:$A$49,"All landing pages",Totals!$B$5:$B$49,"Organic",Totals!$C$5:$C$49,"Desktop") | G29: =SUMIFS(Totals!$P$5:$P$49,Totals!$A$5:$A$49,"All landing pages",Totals!$B$5:$B$49,"Organic",Totals!$C$5:$C$49,"Desktop") | H29: =IF(OR(F29="",G29="",G29=0,F29=0),"",G29/F29-1) | I29: =SUMIFS(Totals!$AQ$5:$AQ$49,Totals!$A$5:$A$49,"All landing pages",Totals!$B$5:$B$49,"Organic",Totals!$C$5:$C$49,"Desktop") | J29: =SUMIFS(Totals!$AR$5:$AR$49,Totals!$A$5:$A$49,"All landing pages",Totals!$B$5:$B$49,"Organic",Totals!$C$5:$C$49,"Desktop") | K29: =IF(OR(I29="",J29="",J29=0,I29=0),"",J29/I29-1) | L29: =IF(OR(F29="",C29="",C29=0),"",F29/C29) | M29: =IF(OR(G29="",D29="",D29=0),"",G29/D29) | N29: =IF(OR(L29="",M29=""),"",(M29-L29)*100) | O29: =IF(OR(I29="",F29="",F29=0),"",I29/F29) | P29: =IF(OR(J29="",G29="",G29=0),"",J29/G29) | Q29: =IF(OR(O29="",P29=""),"",(P29-O29)*100) | R29: =IF(OR(I29="",C29="",C29=0),"",I29/C29) | S29: =IF(OR(J29="",D29="",D29=0),"",J29/D29) | T29: =IF(OR(R29="",S29=""),"",(S29-R29)*100)
A30: Direct | B30: Mobile | C30: =SUMIFS(Totals!$D$5:$D$49,Totals!$A$5:$A$49,"All landing pages",Totals!$B$5:$B$49,"Direct",Totals!$C$5:$C$49,"Mobile") | D30: =SUMIFS(Totals!$E$5:$E$49,Totals!$A$5:$A$49,"All landing pages",Totals!$B$5:$B$49,"Direct",Totals!$C$5:$C$49,"Mobile") | E30: =IF(OR(C30="",D30="",D30=0,C30=0),"",D30/C30-1) | F30: =SUMIFS(Totals!$O$5:$O$49,Totals!$A$5:$A$49,"All landing pages",Totals!$B$5:$B$49,"Direct",Totals!$C$5:$C$49,"Mobile") | G30: =SUMIFS(Totals!$P$5:$P$49,Totals!$A$5:$A$49,"All landing pages",Totals!$B$5:$B$49,"Direct",Totals!$C$5:$C$49,"Mobile") | H30: =IF(OR(F30="",G30="",G30=0,F30=0),"",G30/F30-1) | I30: =SUMIFS(Totals!$AQ$5:$AQ$49,Totals!$A$5:$A$49,"All landing pages",Totals!$B$5:$B$49,"Direct",Totals!$C$5:$C$49,"Mobile") | J30: =SUMIFS(Totals!$AR$5:$AR$49,Totals!$A$5:$A$49,"All landing pages",Totals!$B$5:$B$49,"Direct",Totals!$C$5:$C$49,"Mobile") | K30: =IF(OR(I30="",J30="",J30=0,I30=0),"",J30/I30-1) | L30: =IF(OR(F30="",C30="",C30=0),"",F30/C30) | M30: =IF(OR(G30="",D30="",D30=0),"",G30/D30) | N30: =IF(OR(L30="",M30=""),"",(M30-L30)*100) | O30: =IF(OR(I30="",F30="",F30=0),"",I30/F30) | P30: =IF(OR(J30="",G30="",G30=0),"",J30/G30) | Q30: =IF(OR(O30="",P30=""),"",(P30-O30)*100) | R30: =IF(OR(I30="",C30="",C30=0),"",I30/C30) | S30: =IF(OR(J30="",D30="",D30=0),"",J30/D30) | T30: =IF(OR(R30="",S30=""),"",(S30-R30)*100)
A31: Direct | B31: Desktop | C31: =SUMIFS(Totals!$D$5:$D$49,Totals!$A$5:$A$49,"All landing pages",Totals!$B$5:$B$49,"Direct",Totals!$C$5:$C$49,"Desktop") | D31: =SUMIFS(Totals!$E$5:$E$49,Totals!$A$5:$A$49,"All landing pages",Totals!$B$5:$B$49,"Direct",Totals!$C$5:$C$49,"Desktop") | E31: =IF(OR(C31="",D31="",D31=0,C31=0),"",D31/C31-1) | F31: =SUMIFS(Totals!$O$5:$O$49,Totals!$A$5:$A$49,"All landing pages",Totals!$B$5:$B$49,"Direct",Totals!$C$5:$C$49,"Desktop") | G31: =SUMIFS(Totals!$P$5:$P$49,Totals!$A$5:$A$49,"All landing pages",Totals!$B$5:$B$49,"Direct",Totals!$C$5:$C$49,"Desktop") | H31: =IF(OR(F31="",G31="",G31=0,F31=0),"",G31/F31-1) | I31: =SUMIFS(Totals!$AQ$5:$AQ$49,Totals!$A$5:$A$49,"All landing pages",Totals!$B$5:$B$49,"Direct",Totals!$C$5:$C$49,"Desktop") | J31: =SUMIFS(Totals!$AR$5:$AR$49,Totals!$A$5:$A$49,"All landing pages",Totals!$B$5:$B$49,"Direct",Totals!$C$5:$C$49,"Desktop") | K31: =IF(OR(I31="",J31="",J31=0,I31=0),"",J31/I31-1) | L31: =IF(OR(F31="",C31="",C31=0),"",F31/C31) | M31: =IF(OR(G31="",D31="",D31=0),"",G31/D31) | N31: =IF(OR(L31="",M31=""),"",(M31-L31)*100) | O31: =IF(OR(I31="",F31="",F31=0),"",I31/F31) | P31: =IF(OR(J31="",G31="",G31=0),"",J31/G31) | Q31: =IF(OR(O31="",P31=""),"",(P31-O31)*100) | R31: =IF(OR(I31="",C31="",C31=0),"",I31/C31) | S31: =IF(OR(J31="",D31="",D31=0),"",J31/D31) | T31: =IF(OR(R31="",S31=""),"",(S31-R31)*100)
A33: By market (all landing pages, all channels, Mobile + Desktop — Looker visible rows only)
A34: United Kingdom | B34: All | C34: =IF(SUMIFS(Countries!$E$5:$E$434,Countries!$A$5:$A$434,"All landing pages",Countries!$D$5:$D$434,$A34)=0,"",SUMIFS(Countries!$E$5:$E$434,Countries!$A$5:$A$434,"All landing pages",Countries!$D$5:$D$434,$A34)) | D34: =IF(SUMIFS(Countries!$F$5:$F$434,Countries!$A$5:$A$434,"All landing pages",Countries!$D$5:$D$434,$A34)=0,"",SUMIFS(Countries!$F$5:$F$434,Countries!$A$5:$A$434,"All landing pages",Countries!$D$5:$D$434,$A34)) | E34: =IF(OR(C34="",D34="",D34=0,C34=0),"",D34/C34-1) | F34: =IF(SUMIFS(Countries!$P$5:$P$434,Countries!$A$5:$A$434,"All landing pages",Countries!$D$5:$D$434,$A34)=0,"",SUMIFS(Countries!$P$5:$P$434,Countries!$A$5:$A$434,"All landing pages",Countries!$D$5:$D$434,$A34)) | G34: =IF(SUMIFS(Countries!$Q$5:$Q$434,Countries!$A$5:$A$434,"All landing pages",Countries!$D$5:$D$434,$A34)=0,"",SUMIFS(Countries!$Q$5:$Q$434,Countries!$A$5:$A$434,"All landing pages",Countries!$D$5:$D$434,$A34)) | H34: =IF(OR(F34="",G34="",G34=0,F34=0),"",G34/F34-1) | I34: =IF(SUMIFS(Countries!$AR$5:$AR$434,Countries!$A$5:$A$434,"All landing pages",Countries!$D$5:$D$434,$A34)=0,"",SUMIFS(Countries!$AR$5:$AR$434,Countries!$A$5:$A$434,"All landing pages",Countries!$D$5:$D$434,$A34)) | J34: =IF(SUMIFS(Countries!$AS$5:$AS$434,Countries!$A$5:$A$434,"All landing pages",Countries!$D$5:$D$434,$A34)=0,"",SUMIFS(Countries!$AS$5:$AS$434,Countries!$A$5:$A$434,"All landing pages",Countries!$D$5:$D$434,$A34)) | K34: =IF(OR(I34="",J34="",J34=0,I34=0),"",J34/I34-1) | L34: =IF(SUMIFS(Countries!$E$5:$E$434,Countries!$A$5:$A$434,"All landing pages",Countries!$D$5:$D$434,$A34,Countries!$P$5:$P$434,">0")=0,"",SUMIFS(Countries!$P$5:$P$434,Countries!$A$5:$A$434,"All landing pages",Countries!$D$5:$D$434,$A34,Countries!$E$5:$E$434,">0")/SUMIFS(Countries!$E$5:$E$434,Countries!$A$5:$A$434,"All landing pages",Countries!$D$5:$D$434,$A34,Countries!$P$5:$P$434,">0")) | M34: =IF(SUMIFS(Countries!$F$5:$F$434,Countries!$A$5:$A$434,"All landing pages",Countries!$D$5:$D$434,$A34,Countries!$Q$5:$Q$434,">0")=0,"",SUMIFS(Countries!$Q$5:$Q$434,Countries!$A$5:$A$434,"All landing pages",Countries!$D$5:$D$434,$A34,Countries!$F$5:$F$434,">0")/SUMIFS(Countries!$F$5:$F$434,Countries!$A$5:$A$434,"All landing pages",Countries!$D$5:$D$434,$A34,Countries!$Q$5:$Q$434,">0")) | N34: =IF(OR(L34="",M34=""),"",(M34-L34)*100) | O34: =IF(SUMIFS(Countries!$P$5:$P$434,Countries!$A$5:$A$434,"All landing pages",Countries!$D$5:$D$434,$A34,Countries!$AR$5:$AR$434,">0")=0,"",SUMIFS(Countries!$AR$5:$AR$434,Countries!$A$5:$A$434,"All landing pages",Countries!$D$5:$D$434,$A34,Countries!$P$5:$P$434,">0")/SUMIFS(Countries!$P$5:$P$434,Countries!$A$5:$A$434,"All landing pages",Countries!$D$5:$D$434,$A34,Countries!$AR$5:$AR$434,">0")) | P34: =IF(SUMIFS(Countries!$Q$5:$Q$434,Countries!$A$5:$A$434,"All landing pages",Countries!$D$5:$D$434,$A34,Countries!$AS$5:$AS$434,">0")=0,"",SUMIFS(Countries!$AS$5:$AS$434,Countries!$A$5:$A$434,"All landing pages",Countries!$D$5:$D$434,$A34,Countries!$Q$5:$Q$434,">0")/SUMIFS(Countries!$Q$5:$Q$434,Countries!$A$5:$A$434,"All landing pages",Countries!$D$5:$D$434,$A34,Countries!$AS$5:$AS$434,">0")) | Q34: =IF(OR(O34="",P34=""),"",(P34-O34)*100) | R34: =IF(SUMIFS(Countries!$E$5:$E$434,Countries!$A$5:$A$434,"All landing pages",Countries!$D$5:$D$434,$A34,Countries!$AR$5:$AR$434,">0")=0,"",SUMIFS(Countries!$AR$5:$AR$434,Countries!$A$5:$A$434,"All landing pages",Countries!$D$5:$D$434,$A34,Countries!$E$5:$E$434,">0")/SUMIFS(Countries!$E$5:$E$434,Countries!$A$5:$A$434,"All landing pages",Countries!$D$5:$D$434,$A34,Countries!$AR$5:$AR$434,">0")) | S34: =IF(SUMIFS(Countries!$F$5:$F$434,Countries!$A$5:$A$434,"All landing pages",Countries!$D$5:$D$434,$A34,Countries!$AS$5:$AS$434,">0")=0,"",SUMIFS(Countries!$AS$5:$AS$434,Countries!$A$5:$A$434,"All landing pages",Countries!$D$5:$D$434,$A34,Countries!$F$5:$F$434,">0")/SUMIFS(Countries!$F$5:$F$434,Countries!$A$5:$A$434,"All landing pages",Countries!$D$5:$D$434,$A34,Countries!$AS$5:$AS$434,">0")) | T34: =IF(OR(R34="",S34=""),"",(S34-R34)*100)
A35: Germany | B35: All | C35: =IF(SUMIFS(Countries!$E$5:$E$434,Countries!$A$5:$A$434,"All landing pages",Countries!$D$5:$D$434,$A35)=0,"",SUMIFS(Countries!$E$5:$E$434,Countries!$A$5:$A$434,"All landing pages",Countries!$D$5:$D$434,$A35)) | D35: =IF(SUMIFS(Countries!$F$5:$F$434,Countries!$A$5:$A$434,"All landing pages",Countries!$D$5:$D$434,$A35)=0,"",SUMIFS(Countries!$F$5:$F$434,Countries!$A$5:$A$434,"All landing pages",Countries!$D$5:$D$434,$A35)) | E35: =IF(OR(C35="",D35="",D35=0,C35=0),"",D35/C35-1) | F35: =IF(SUMIFS(Countries!$P$5:$P$434,Countries!$A$5:$A$434,"All landing pages",Countries!$D$5:$D$434,$A35)=0,"",SUMIFS(Countries!$P$5:$P$434,Countries!$A$5:$A$434,"All landing pages",Countries!$D$5:$D$434,$A35)) | G35: =IF(SUMIFS(Countries!$Q$5:$Q$434,Countries!$A$5:$A$434,"All landing pages",Countries!$D$5:$D$434,$A35)=0,"",SUMIFS(Countries!$Q$5:$Q$434,Countries!$A$5:$A$434,"All landing pages",Countries!$D$5:$D$434,$A35)) | H35: =IF(OR(F35="",G35="",G35=0,F35=0),"",G35/F35-1) | I35: =IF(SUMIFS(Countries!$AR$5:$AR$434,Countries!$A$5:$A$434,"All landing pages",Countries!$D$5:$D$434,$A35)=0,"",SUMIFS(Countries!$AR$5:$AR$434,Countries!$A$5:$A$434,"All landing pages",Countries!$D$5:$D$434,$A35)) | J35: =IF(SUMIFS(Countries!$AS$5:$AS$434,Countries!$A$5:$A$434,"All landing pages",Countries!$D$5:$D$434,$A35)=0,"",SUMIFS(Countries!$AS$5:$AS$434,Countries!$A$5:$A$434,"All landing pages",Countries!$D$5:$D$434,$A35)) | K35: =IF(OR(I35="",J35="",J35=0,I35=0),"",J35/I35-1) | L35: =IF(SUMIFS(Countries!$E$5:$E$434,Countries!$A$5:$A$434,"All landing pages",Countries!$D$5:$D$434,$A35,Countries!$P$5:$P$434,">0")=0,"",SUMIFS(Countries!$P$5:$P$434,Countries!$A$5:$A$434,"All landing pages",Countries!$D$5:$D$434,$A35,Countries!$E$5:$E$434,">0")/SUMIFS(Countries!$E$5:$E$434,Countries!$A$5:$A$434,"All landing pages",Countries!$D$5:$D$434,$A35,Countries!$P$5:$P$434,">0")) | M35: =IF(SUMIFS(Countries!$F$5:$F$434,Countries!$A$5:$A$434,"All landing pages",Countries!$D$5:$D$434,$A35,Countries!$Q$5:$Q$434,">0")=0,"",SUMIFS(Countries!$Q$5:$Q$434,Countries!$A$5:$A$434,"All landing pages",Countries!$D$5:$D$434,$A35,Countries!$F$5:$F$434,">0")/SUMIFS(Countries!$F$5:$F$434,Countries!$A$5:$A$434,"All landing pages",Countries!$D$5:$D$434,$A35,Countries!$Q$5:$Q$434,">0")) | N35: =IF(OR(L35="",M35=""),"",(M35-L35)*100) | O35: =IF(SUMIFS(Countries!$P$5:$P$434,Countries!$A$5:$A$434,"All landing pages",Countries!$D$5:$D$434,$A35,Countries!$AR$5:$AR$434,">0")=0,"",SUMIFS(Countries!$AR$5:$AR$434,Countries!$A$5:$A$434,"All landing pages",Countries!$D$5:$D$434,$A35,Countries!$P$5:$P$434,">0")/SUMIFS(Countries!$P$5:$P$434,Countries!$A$5:$A$434,"All landing pages",Countries!$D$5:$D$434,$A35,Countries!$AR$5:$AR$434,">0")) | P35: =IF(SUMIFS(Countries!$Q$5:$Q$434,Countries!$A$5:$A$434,"All landing pages",Countries!$D$5:$D$434,$A35,Countries!$AS$5:$AS$434,">0")=0,"",SUMIFS(Countries!$AS$5:$AS$434,Countries!$A$5:$A$434,"All landing pages",Countries!$D$5:$D$434,$A35,Countries!$Q$5:$Q$434,">0")/SUMIFS(Countries!$Q$5:$Q$434,Countries!$A$5:$A$434,"All landing pages",Countries!$D$5:$D$434,$A35,Countries!$AS$5:$AS$434,">0")) | Q35: =IF(OR(O35="",P35=""),"",(P35-O35)*100) | R35: =IF(SUMIFS(Countries!$E$5:$E$434,Countries!$A$5:$A$434,"All landing pages",Countries!$D$5:$D$434,$A35,Countries!$AR$5:$AR$434,">0")=0,"",SUMIFS(Countries!$AR$5:$AR$434,Countries!$A$5:$A$434,"All landing pages",Countries!$D$5:$D$434,$A35,Countries!$E$5:$E$434,">0")/SUMIFS(Countries!$E$5:$E$434,Countries!$A$5:$A$434,"All landing pages",Countries!$D$5:$D$434,$A35,Countries!$AR$5:$AR$434,">0")) | S35: =IF(SUMIFS(Countries!$F$5:$F$434,Countries!$A$5:$A$434,"All landing pages",Countries!$D$5:$D$434,$A35,Countries!$AS$5:$AS$434,">0")=0,"",SUMIFS(Countries!$AS$5:$AS$434,Countries!$A$5:$A$434,"All landing pages",Countries!$D$5:$D$434,$A35,Countries!$F$5:$F$434,">0")/SUMIFS(Countries!$F$5:$F$434,Countries!$A$5:$A$434,"All landing pages",Countries!$D$5:$D$434,$A35,Countries!$AS$5:$AS$434,">0")) | T35: =IF(OR(R35="",S35=""),"",(S35-R35)*100)
A36: Italy | B36: All | C36: =IF(SUMIFS(Countries!$E$5:$E$434,Countries!$A$5:$A$434,"All landing pages",Countries!$D$5:$D$434,$A36)=0,"",SUMIFS(Countries!$E$5:$E$434,Countries!$A$5:$A$434,"All landing pages",Countries!$D$5:$D$434,$A36)) | D36: =IF(SUMIFS(Countries!$F$5:$F$434,Countries!$A$5:$A$434,"All landing pages",Countries!$D$5:$D$434,$A36)=0,"",SUMIFS(Countries!$F$5:$F$434,Countries!$A$5:$A$434,"All landing pages",Countries!$D$5:$D$434,$A36)) | E36: =IF(OR(C36="",D36="",D36=0,C36=0),"",D36/C36-1) | F36: =IF(SUMIFS(Countries!$P$5:$P$434,Countries!$A$5:$A$434,"All landing pages",Countries!$D$5:$D$434,$A36)=0,"",SUMIFS(Countries!$P$5:$P$434,Countries!$A$5:$A$434,"All landing pages",Countries!$D$5:$D$434,$A36)) | G36: =IF(SUMIFS(Countries!$Q$5:$Q$434,Countries!$A$5:$A$434,"All landing pages",Countries!$D$5:$D$434,$A36)=0,"",SUMIFS(Countries!$Q$5:$Q$434,Countries!$A$5:$A$434,"All landing pages",Countries!$D$5:$D$434,$A36)) | H36: =IF(OR(F36="",G36="",G36=0,F36=0),"",G36/F36-1) | I36: =IF(SUMIFS(Countries!$AR$5:$AR$434,Countries!$A$5:$A$434,"All landing pages",Countries!$D$5:$D$434,$A36)=0,"",SUMIFS(Countries!$AR$5:$AR$434,Countries!$A$5:$A$434,"All landing pages",Countries!$D$5:$D$434,$A36)) | J36: =IF(SUMIFS(Countries!$AS$5:$AS$434,Countries!$A$5:$A$434,"All landing pages",Countries!$D$5:$D$434,$A36)=0,"",SUMIFS(Countries!$AS$5:$AS$434,Countries!$A$5:$A$434,"All landing pages",Countries!$D$5:$D$434,$A36)) | K36: =IF(OR(I36="",J36="",J36=0,I36=0),"",J36/I36-1) | L36: =IF(SUMIFS(Countries!$E$5:$E$434,Countries!$A$5:$A$434,"All landing pages",Countries!$D$5:$D$434,$A36,Countries!$P$5:$P$434,">0")=0,"",SUMIFS(Countries!$P$5:$P$434,Countries!$A$5:$A$434,"All landing pages",Countries!$D$5:$D$434,$A36,Countries!$E$5:$E$434,">0")/SUMIFS(Countries!$E$5:$E$434,Countries!$A$5:$A$434,"All landing pages",Countries!$D$5:$D$434,$A36,Countries!$P$5:$P$434,">0")) | M36: =IF(SUMIFS(Countries!$F$5:$F$434,Countries!$A$5:$A$434,"All landing pages",Countries!$D$5:$D$434,$A36,Countries!$Q$5:$Q$434,">0")=0,"",SUMIFS(Countries!$Q$5:$Q$434,Countries!$A$5:$A$434,"All landing pages",Countries!$D$5:$D$434,$A36,Countries!$F$5:$F$434,">0")/SUMIFS(Countries!$F$5:$F$434,Countries!$A$5:$A$434,"All landing pages",Countries!$D$5:$D$434,$A36,Countries!$Q$5:$Q$434,">0")) | N36: =IF(OR(L36="",M36=""),"",(M36-L36)*100) | O36: =IF(SUMIFS(Countries!$P$5:$P$434,Countries!$A$5:$A$434,"All landing pages",Countries!$D$5:$D$434,$A36,Countries!$AR$5:$AR$434,">0")=0,"",SUMIFS(Countries!$AR$5:$AR$434,Countries!$A$5:$A$434,"All landing pages",Countries!$D$5:$D$434,$A36,Countries!$P$5:$P$434,">0")/SUMIFS(Countries!$P$5:$P$434,Countries!$A$5:$A$434,"All landing pages",Countries!$D$5:$D$434,$A36,Countries!$AR$5:$AR$434,">0")) | P36: =IF(SUMIFS(Countries!$Q$5:$Q$434,Countries!$A$5:$A$434,"All landing pages",Countries!$D$5:$D$434,$A36,Countries!$AS$5:$AS$434,">0")=0,"",SUMIFS(Countries!$AS$5:$AS$434,Countries!$A$5:$A$434,"All landing pages",Countries!$D$5:$D$434,$A36,Countries!$Q$5:$Q$434,">0")/SUMIFS(Countries!$Q$5:$Q$434,Countries!$A$5:$A$434,"All landing pages",Countries!$D$5:$D$434,$A36,Countries!$AS$5:$AS$434,">0")) | Q36: =IF(OR(O36="",P36=""),"",(P36-O36)*100) | R36: =IF(SUMIFS(Countries!$E$5:$E$434,Countries!$A$5:$A$434,"All landing pages",Countries!$D$5:$D$434,$A36,Countries!$AR$5:$AR$434,">0")=0,"",SUMIFS(Countries!$AR$5:$AR$434,Countries!$A$5:$A$434,"All landing pages",Countries!$D$5:$D$434,$A36,Countries!$E$5:$E$434,">0")/SUMIFS(Countries!$E$5:$E$434,Countries!$A$5:$A$434,"All landing pages",Countries!$D$5:$D$434,$A36,Countries!$AR$5:$AR$434,">0")) | S36: =IF(SUMIFS(Countries!$F$5:$F$434,Countries!$A$5:$A$434,"All landing pages",Countries!$D$5:$D$434,$A36,Countries!$AS$5:$AS$434,">0")=0,"",SUMIFS(Countries!$AS$5:$AS$434,Countries!$A$5:$A$434,"All landing pages",Countries!$D$5:$D$434,$A36,Countries!$F$5:$F$434,">0")/SUMIFS(Countries!$F$5:$F$434,Countries!$A$5:$A$434,"All landing pages",Countries!$D$5:$D$434,$A36,Countries!$AS$5:$AS$434,">0")) | T36: =IF(OR(R36="",S36=""),"",(S36-R36)*100)
A37: Spain | B37: All | C37: =IF(SUMIFS(Countries!$E$5:$E$434,Countries!$A$5:$A$434,"All landing pages",Countries!$D$5:$D$434,$A37)=0,"",SUMIFS(Countries!$E$5:$E$434,Countries!$A$5:$A$434,"All landing pages",Countries!$D$5:$D$434,$A37)) | D37: =IF(SUMIFS(Countries!$F$5:$F$434,Countries!$A$5:$A$434,"All landing pages",Countries!$D$5:$D$434,$A37)=0,"",SUMIFS(Countries!$F$5:$F$434,Countries!$A$5:$A$434,"All landing pages",Countries!$D$5:$D$434,$A37)) | E37: =IF(OR(C37="",D37="",D37=0,C37=0),"",D37/C37-1) | F37: =IF(SUMIFS(Countries!$P$5:$P$434,Countries!$A$5:$A$434,"All landing pages",Countries!$D$5:$D$434,$A37)=0,"",SUMIFS(Countries!$P$5:$P$434,Countries!$A$5:$A$434,"All landing pages",Countries!$D$5:$D$434,$A37)) | G37: =IF(SUMIFS(Countries!$Q$5:$Q$434,Countries!$A$5:$A$434,"All landing pages",Countries!$D$5:$D$434,$A37)=0,"",SUMIFS(Countries!$Q$5:$Q$434,Countries!$A$5:$A$434,"All landing pages",Countries!$D$5:$D$434,$A37)) | H37: =IF(OR(F37="",G37="",G37=0,F37=0),"",G37/F37-1) | I37: =IF(SUMIFS(Countries!$AR$5:$AR$434,Countries!$A$5:$A$434,"All landing pages",Countries!$D$5:$D$434,$A37)=0,"",SUMIFS(Countries!$AR$5:$AR$434,Countries!$A$5:$A$434,"All landing pages",Countries!$D$5:$D$434,$A37)) | J37: =IF(SUMIFS(Countries!$AS$5:$AS$434,Countries!$A$5:$A$434,"All landing pages",Countries!$D$5:$D$434,$A37)=0,"",SUMIFS(Countries!$AS$5:$AS$434,Countries!$A$5:$A$434,"All landing pages",Countries!$D$5:$D$434,$A37)) | K37: =IF(OR(I37="",J37="",J37=0,I37=0),"",J37/I37-1) | L37: =IF(SUMIFS(Countries!$E$5:$E$434,Countries!$A$5:$A$434,"All landing pages",Countries!$D$5:$D$434,$A37,Countries!$P$5:$P$434,">0")=0,"",SUMIFS(Countries!$P$5:$P$434,Countries!$A$5:$A$434,"All landing pages",Countries!$D$5:$D$434,$A37,Countries!$E$5:$E$434,">0")/SUMIFS(Countries!$E$5:$E$434,Countries!$A$5:$A$434,"All landing pages",Countries!$D$5:$D$434,$A37,Countries!$P$5:$P$434,">0")) | M37: =IF(SUMIFS(Countries!$F$5:$F$434,Countries!$A$5:$A$434,"All landing pages",Countries!$D$5:$D$434,$A37,Countries!$Q$5:$Q$434,">0")=0,"",SUMIFS(Countries!$Q$5:$Q$434,Countries!$A$5:$A$434,"All landing pages",Countries!$D$5:$D$434,$A37,Countries!$F$5:$F$434,">0")/SUMIFS(Countries!$F$5:$F$434,Countries!$A$5:$A$434,"All landing pages",Countries!$D$5:$D$434,$A37,Countries!$Q$5:$Q$434,">0")) | N37: =IF(OR(L37="",M37=""),"",(M37-L37)*100) | O37: =IF(SUMIFS(Countries!$P$5:$P$434,Countries!$A$5:$A$434,"All landing pages",Countries!$D$5:$D$434,$A37,Countries!$AR$5:$AR$434,">0")=0,"",SUMIFS(Countries!$AR$5:$AR$434,Countries!$A$5:$A$434,"All landing pages",Countries!$D$5:$D$434,$A37,Countries!$P$5:$P$434,">0")/SUMIFS(Countries!$P$5:$P$434,Countries!$A$5:$A$434,"All landing pages",Countries!$D$5:$D$434,$A37,Countries!$AR$5:$AR$434,">0")) | P37: =IF(SUMIFS(Countries!$Q$5:$Q$434,Countries!$A$5:$A$434,"All landing pages",Countries!$D$5:$D$434,$A37,Countries!$AS$5:$AS$434,">0")=0,"",SUMIFS(Countries!$AS$5:$AS$434,Countries!$A$5:$A$434,"All landing pages",Countries!$D$5:$D$434,$A37,Countries!$Q$5:$Q$434,">0")/SUMIFS(Countries!$Q$5:$Q$434,Countries!$A$5:$A$434,"All landing pages",Countries!$D$5:$D$434,$A37,Countries!$AS$5:$AS$434,">0")) | Q37: =IF(OR(O37="",P37=""),"",(P37-O37)*100) | R37: =IF(SUMIFS(Countries!$E$5:$E$434,Countries!$A$5:$A$434,"All landing pages",Countries!$D$5:$D$434,$A37,Countries!$AR$5:$AR$434,">0")=0,"",SUMIFS(Countries!$AR$5:$AR$434,Countries!$A$5:$A$434,"All landing pages",Countries!$D$5:$D$434,$A37,Countries!$E$5:$E$434,">0")/SUMIFS(Countries!$E$5:$E$434,Countries!$A$5:$A$434,"All landing pages",Countries!$D$5:$D$434,$A37,Countries!$AR$5:$AR$434,">0")) | S37: =IF(SUMIFS(Countries!$F$5:$F$434,Countries!$A$5:$A$434,"All landing pages",Countries!$D$5:$D$434,$A37,Countries!$AS$5:$AS$434,">0")=0,"",SUMIFS(Countries!$AS$5:$AS$434,Countries!$A$5:$A$434,"All landing pages",Countries!$D$5:$D$434,$A37,Countries!$F$5:$F$434,">0")/SUMIFS(Countries!$F$5:$F$434,Countries!$A$5:$A$434,"All landing pages",Countries!$D$5:$D$434,$A37,Countries!$AS$5:$AS$434,">0")) | T37: =IF(OR(R37="",S37=""),"",(S37-R37)*100)
